Workbook

Sheet اسلامیات
A1: د عامی روغتیا وزارت
A2: د خصوصي روغتیايي علومو انستېتوتونو ریاست
A3: مومن د طبی علومو انستیتوت
A4: علمی او تحقیقاتی معاونیت
A5: تدریسي مدیریت
A6: ازموینو کمیټه
B7: چانس: لومړی | G7: وخت : ۹بجی | L7: سمستر:لومړی بهاری | P7: غاښونو پروتیز | Q7: څانګه :
A9: 1403/06/17 | E9: نیټه : | H9: ازموینه:نهايي | L9: استاد : مولوی مولاجان | P9: مضمون : اسلامی ثقافت
A11: کتني | B11: مجموعه | D11: 60فیصده نمبری | E11: 20فیصده نمبری | F11: حاضری/صنفي | G11: پیژندنه | I11: ګڼه | J11: کتني | K11: مجموعه | M11: 60فیصده نمبری | N11: 20فیصده نمبری | O11: حاضری/صنفي | P11: پیژندنه | R11: ګڼه
B12: حروفی | C12: عددی | G12: د پلار نوم | H12: نوم | K12: حروفی | L12: عددی | P12: د پلار نوم | Q12: نوم
I13: 1 | K13: اتیا | L13: =SUM(M13:O13) -> 80 | M13: 45 | N13: 15 | O13: 20 | P13: هدایت الله | Q13: نایب احمد | R13: 1
I14: 2 | K14: اتیا | L14: =SUM(M14:O14) -> 80 | M14: 42 | N14: 18 | O14: 20 | P14: حاجی نصیر | Q14: عازی | R14: 2
I15: 3 | K15: دوه نوي | L15: =SUM(M15:O15) -> 92 | M15: 55 | N15: 17 | O15: 20 | P15: محمدقلم | Q15: حضرت علی | R15: 3
I16: 4 | K16: پنځه نوي | L16: =SUM(M16:O16) -> 95 | M16: 56 | N16: 19 | O16: 20 | P16: خوانی | Q16: وحید الله | R16: 4
I17: 5 | K17: اته اتیا | L17: =SUM(M17:O17) -> 88 | M17: 56 | N17: 12 | O17: 20 | P17: سربلند | Q17: نعمت الله | R17: 5
I18: 6 | K18: اوه اتیا | L18: =SUM(M18:O18) -> 87 | M18: 52 | N18: 15 | O18: 20 | P18: جلاد خان | Q18: ابراهیم | R18: 6
I19: 7 | K19: پنځه اویا | L19: =SUM(M19:O19) -> 75 | M19: 48 | N19: 7 | O19: 20 | P19: سیدالرحمن | Q19: مطیع الرحمن | R19: 7
I20: 8 | K20: څلور نوي | L20: =SUM(M20:O20) -> 94 | M20: 54 | N20: 20 | O20: 20 | P20: صبرشاه | Q20: عمران خان | R20: 8
I21: 9 | K21: شپږ اتیا | L21: =SUM(M21:O21) -> 86 | M21: 57 | N21: 9 | O21: 20 | P21: سید مصیر | Q21: سیدحکمت الله | R21: 9
I22: 10 | K22: اویا | L22: =SUM(M22:O22) -> 70 | M22: 41 | N22: 9 | O22: 20 | P22: هجرت الله | Q22: نصرت | R22: 10
I23: 11 | K23: اویا | L23: =SUM(M23:O23) -> 70 | M23: 43 | N23: 7 | O23: 20 | P23: محمد امین | Q23: سید امین | R23: 11
I24: 12 | K24: څلور نوي | L24: =SUM(M24:O24) -> 94 | M24: 54 | N24: 20 | O24: 20 | P24: شمشیر | Q24: رحمن الله | R24: 12
... I30: 18 | K30: اوه اتیا | L30: =SUM(M30:O30) -> 87 | M30: 48 | N30: 19 | O30: 20 | P30: فضل هادی | Q30: هلال | R30: 18
I31: 66 | R31: 19
I32: 67 | R32: 20
I33: 68 | R33: 21
I34: 69 | R34: 27
I35: 70 | R35: 32
I36: 71 | R36: 33
I37: 72 | R37: 34
I38: 73 | R38: 35
I39: 74 | R39: 36
I40: 75 | R40: 37
I41: 76 | R41: 38
A42: پورتنۍ نمبري د ازمویني له پرچو څخه له قلم خوری پرته شقي ته رسیدلي درست دي
E43: ممیزلاسلیک | M43: ممتحن لاسلیک

Sheet عمومي ترمینالوژی
A1: د عامی روغتیا وزارت
A2: د خصوصي روغتیايي علومو انستېتوتونو ریاست
A3: مومن د طبی علومو انستیتوت
A4: علمی او تحقیقاتی معاونیت
A5: تدریسي مدیریت
A6: ازموینو کمیټه
B7: چانس: لومړی | G7: وخت : ۹بجی | L7: سمستر:لومړی بهاری | P7: غاښونو پروتیز | Q7: څانګه :
A9: 1403/06/17 | E9: نیټه : | H9: ازموینه:نهايي | L9: استاد : اشرف زهیر | P9: مضمون : طبی ترمینالوژی
A11: کتني | B11: مجموعه | D11: 60فیصده نمبری | E11: 20فیصده نمبری | F11: حاضری/صنفي | G11: پیژندنه | I11: ګڼه | J11: کتني | K11: مجموعه | M11: 60فیصده نمبری | N11: 20فیصده نمبری | O11: حاضری/صنفي | P11: پیژندنه | R11: ګڼه
B12: حروفی | C12: عددی | G12: د پلار نوم | H12: نوم | K12: حروفی | L12: عددی | P12: د پلار نوم | Q12: نوم
I13: 1 | K13: یو نوي | L13: =SUM(M13:O13) -> 91 | M13: 53 | N13: 18 | O13: 20 | P13: هدایت الله | Q13: نایب احمد | R13: 1
I14: 2 | K14: شپږ اویا | L14: =SUM(M14:O14) -> 76 | M14: 38 | N14: 18 | O14: 20 | P14: حاجی نصیر | Q14: عازی | R14: 2
I15: 3 | K15: شپېته | L15: =SUM(M15:O15) -> 60 | M15: 33 | N15: 7 | O15: 20 | P15: محمدقلم | Q15: حضرت علی | R15: 3
I16: 4 | K16: سل | L16: =SUM(M16:O16) -> 100 | M16: 60 | N16: 20 | O16: 20 | P16: خوانی | Q16: وحید الله | R16: 4
I17: 5 | K17: دوه نوي | L17: =SUM(M17:O17) -> 92 | M17: 52 | N17: 20 | O17: 20 | P17: سربلند | Q17: نعمت الله | R17: 5
I18: 6 | K18: اته اتیا | L18: =SUM(M18:O18) -> 88 | M18: 54 | N18: 14 | O18: 20 | P18: جلاد خان | Q18: ابراهیم | R18: 6
I19: 7 | K19: اتیا | L19: =SUM(M19:O19) -> 80 | M19: 55 | N19: 5 | O19: 20 | P19: سیدالرحمن | Q19: مطیع الرحمن | R19: 7
I20: 8 | K20: نوي | L20: =SUM(M20:O20) -> 90 | M20: 58 | N20: 12 | O20: 20 | P20: صبرشاه | Q20: عمران خان | R20: 8
I21: 9 | K21: سل | L21: =SUM(M21:O21) -> 100 | M21: 60 | N21: 20 | O21: 20 | P21: سید مصیر | Q21: سیدحکمت الله | R21: 9
I22: 10 | K22: اوه اویا | L22: =SUM(M22:O22) -> 77 | M22: 38 | N22: 19 | O22: 20 | P22: هجرت الله | Q22: نصرت | R22: 10
I23: 11 | K23: څلور اتیا | L23: =SUM(M23:O23) -> 84 | M23: 54 | N23: 10 | O23: 20 | P23: محمد امین | Q23: سید امین | R23: 11
I24: 12 | K24: څلور اویا | L24: =SUM(M24:O24) -> 74 | M24: 44 | N24: 10 | O24: 20 | P24: شمشیر | Q24: رحمن الله | R24: 12
... I30: 18 | K30: څلور اتیا | L30: =SUM(M30:O30) -> 84 | M30: 58 | N30: 6 | O30: 20 | P30: فضل هادی | Q30: هلال | R30: 18
I31: 66 | L31: 0 | R31: 19
I32: 67 | R32: 20
I33: 68 | R33: 21
I34: 69 | R34: 22
I35: 70 | R35: 23
I36: 71 | R36: 29
I37: 72 | R37: 30
I38: 73 | R38: 31
I39: 74 | R39: 32
I40: 75 | R40: 33
I41: 76 | R41: 34
A42: پورتنۍ نمبري د ازمویني له پرچو څخه له قلم خوری پرته شقي ته رسیدلي درست دي
E43: ممیزلاسلیک | M43: ممتحن لاسلیک

Sheet طبي انګلیسي
A1: د عامی روغتیا وزارت
A2: د خصوصي روغتیايي علومو انستېتوتونو ریاست
A3: مومن د طبی علومو انستیتوت
A4: علمی او تحقیقاتی معاونیت
A5: تدریسي مدیریت
A6: ازموینو کمیټه
B7: چانس: لومړی | G7: وخت : ۹بجی | L7: سمستر:لومړی بهاری | P7: غاښونو پروتیز | Q7: څانګه :
A9: 1403/06/14 | E9: نیټه : | H9: ازموینه:نهايي | L9: استاد : عبادالله صمدزی | P9: مضمون :طبی انګلیسي
A11: کتني | B11: مجموعه | D11: 60فیصده نمبری | E11: 20فیصده نمبری | F11: حاضری/صنفي | G11: پیژندنه | I11: ګڼه | J11: کتني | K11: مجموعه | M11: 60فیصده نمبری | N11: 20فیصده نمبری | O11: حاضری/صنفي | P11: پیژندنه | R11: ګڼه
B12: حروفی | C12: عددی | G12: د پلار نوم | H12: نوم | K12: حروفی | L12: عددی | P12: د پلار نوم | Q12: نوم
I13: 1 | K13: درې اتیا | L13: =SUM(M13:O13) -> 83 | M13: 43 | N13: 20 | O13: 20 | P13: هدایت الله | Q13: نایب احمد | R13: 1
I14: 2 | K14: اوه اویا | L14: =SUM(M14:O14) -> 77 | M14: 47 | N14: 10 | O14: 20 | P14: حاجی نصیر | Q14: عازی | R14: 2
I15: 3 | K15: اته نوي | L15: =SUM(M15:O15) -> 98 | M15: 58 | N15: 20 | O15: 20 | P15: محمدقلم | Q15: حضرت علی | R15: 3
I16: 4 | K16: اته نوي | L16: =SUM(M16:O16) -> 98 | M16: 59 | N16: 19 | O16: 20 | P16: خوانی | Q16: وحید الله | R16: 4
I17: 5 | K17: نوي | L17: =SUM(M17:O17) -> 90 | M17: 58 | N17: 12 | O17: 20 | P17: سربلند | Q17: نعمت الله | R17: 5
I18: 6 | K18: شپېته | L18: =SUM(M18:O18) -> 60 | M18: 28 | N18: 12 | O18: 20 | P18: جلاد خان | Q18: ابراهیم | R18: 6
I19: 7 | K19: پنځه اتیا | L19: =SUM(M19:O19) -> 85 | M19: 47 | N19: 18 | O19: 20 | P19: سیدالرحمن | Q19: مطیع الرحمن | R19: 7
I20: 8 | K20: نوي | L20: =SUM(M20:O20) -> 90 | M20: 59 | N20: 11 | O20: 20 | P20: صبرشاه | Q20: عمران خان | R20: 8
I21: 9 | K21: څلور اتیا | L21: =SUM(M21:O21) -> 84 | M21: 57 | N21: 7 | O21: 20 | P21: سید مصیر | Q21: سیدحکمت الله | R21: 9
I22: 10 | K22: اتیا | L22: =SUM(M22:O22) -> 80 | M22: 50 | N22: 10 | O22: 20 | P22: هجرت الله | Q22: نصرت | R22: 10
I23: 11 | K23: سل | L23: =SUM(M23:O23) -> 100 | M23: 60 | N23: 20 | O23: 20 | P23: محمد امین | Q23: سید امین | R23: 11
I24: 12 | K24: پنځه اتیا | L24: =SUM(M24:O24) -> 85 | M24: 54 | N24: 11 | O24: 20 | P24: شمشیر | Q24: رحمن الله | R24: 12
... I30: 18 | K30: نهه نوي | L30: =SUM(M30:O30) -> 99 | M30: 59 | N30: 20 | O30: 20 | P30: فضل هادی | Q30: هلال | R30: 18
I31: 66 | R31: 19
I32: 67 | R32: 20
I33: 68 | R33: 21
I34: 69 | R34: 22
I35: 70 | R35: 23
I36: 71 | R36: 24
I37: 72 | R37: 25
I38: 73 | R38: 26
I39: 74 | R39: 27
I40: 75 | R40: 37
I41: 76 | R41: 38
A42: پورتنۍ نمبري د ازمویني له پرچو څخه له قلم خوری پرته شقي ته رسیدلي درست دي
E43: ممیزلاسلیک | M43: ممتحن لاسلیک

Sheet مورفولوژی
A1: د عامی روغتیا وزارت
A2: د خصوصي روغتیايي علومو انستېتوتونو ریاست
A3: مومن د طبی علومو انستیتوت
A4: علمی او تحقیقاتی معاونیت
A5: تدریسي مدیریت
A6: ازموینو کمیټه
B7: چانس: لومړی | G7: وخت : ۹بجی | L7: سمستر:لومړی بهاری | P7: غاښونو پروتیز | Q7: څانګه :
A9: 1403/06/07 | E9: نیټه : | H9: ازموینه:نهايي | L9: استاد : ذبیح الله فیضي | P9: مضمون :مورفولوژی
A11: کتني | B11: مجموعه | D11: 60فیصده نمبری | E11: 20فیصده نمبری | F11: حاضری/صنفي | G11: پیژندنه | I11: ګڼه | J11: کتني | K11: مجموعه | M11: 60فیصده نمبری | N11: 20فیصده نمبری | O11: حاضری/صنفي | P11: پیژندنه | R11: ګڼه
B12: حروفی | C12: عددی | G12: د پلار نوم | H12: نوم | K12: حروفی | L12: عددی | P12: د پلار نوم | Q12: نوم
I13: 1 | K13: شپږ اتیا | L13: =SUM(M13:O13) -> 86 | M13: 49 | N13: 17 | O13: 20 | P13: هدایت الله | Q13: نایب احمد | R13: 1
I14: 2 | K14: څلور اتیا | L14: =SUM(M14:O14) -> 84 | M14: 48 | N14: 16 | O14: 20 | P14: حاجی نصیر | Q14: عازی | R14: 2
I15: 3 | K15: شپږ پنځوس | L15: =SUM(M15:O15) -> 56 | M15: 26 | N15: 10 | O15: 20 | P15: محمدقلم | Q15: حضرت علی | R15: 3
I16: 4 | K16: نهه اتیا | L16: =SUM(M16:O16) -> 89 | M16: 50 | N16: 19 | O16: 20 | P16: خوانی | Q16: وحید الله | R16: 4
I17: 5 | K17: شپږ نوي | L17: =SUM(M17:O17) -> 96 | M17: 60 | N17: 16 | O17: 20 | P17: سربلند | Q17: نعمت الله | R17: 5
I18: 6 | K18: دوه اتیا | L18: =SUM(M18:O18) -> 82 | M18: 51 | N18: 11 | O18: 20 | P18: جلاد خان | Q18: ابراهیم | R18: 6
I19: 7 | K19: نهه نوي | L19: =SUM(M19:O19) -> 99 | M19: 59 | N19: 20 | O19: 20 | P19: سیدالرحمن | Q19: مطیع الرحمن | R19: 7
I20: 8 | K20: دوه نوي | L20: =SUM(M20:O20) -> 92 | M20: 57 | N20: 15 | O20: 20 | P20: صبرشاه | Q20: عمران خان | R20: 8
I21: 9 | K21: اته اویا | L21: =SUM(M21:O21) -> 78 | M21: 48 | N21: 10 | O21: 20 | P21: سید مصیر | Q21: سیدحکمت الله | R21: 9
I22: 10 | K22: اتیا | L22: =SUM(M22:O22) -> 80 | M22: 51 | N22: 9 | O22: 20 | P22: هجرت الله | Q22: نصرت | R22: 10
I23: 11 | K23: درې نوي | L23: =SUM(M23:O23) -> 93 | M23: 54 | N23: 19 | O23: 20 | P23: محمد امین | Q23: سید امین | R23: 11
I24: 12 | K24: دوه اتیا | L24: =SUM(M24:O24) -> 82 | M24: 56 | N24: 6 | O24: 20 | P24: شمشیر | Q24: رحمن الله | R24: 12
... I30: 18 | K30: شپږ اتیا | L30: =SUM(M30:O30) -> 86 | M30: 48 | N30: 18 | O30: 20 | P30: فضل هادی | Q30: هلال | R30: 18
I31: 66 | R31: 19
I32: 67 | R32: 20
I33: 68 | R33: 21
I34: 69 | R34: 22
I35: 70 | R35: 23
I36: 71 | R36: 24
I37: 72 | R37: 25
I38: 73 | R38: 35
I39: 74 | R39: 36
I40: 75 | R40: 37
I41: 76 | R41: 38
A42: پورتنۍ نمبري د ازمویني له پرچو څخه له قلم خوری پرته شقي ته رسیدلي درست دي
E43: ممیزلاسلیک | M43: ممتحن لاسلیک

Sheet سامان پیژندنه
A1: د عامی روغتیا وزارت
A2: د خصوصي روغتیايي علومو انستېتوتونو ریاست
A3: مومن د طبی علومو انستیتوت
A4: علمی او تحقیقاتی معاونیت
A5: تدریسي مدیریت
A6: ازموینو کمیټه
B7: چانس: لومړی | G7: وخت : ۹بجی | L7: سمستر:لومړی بهاری | P7: غاښونو پروتیز | Q7: څانګه :
A9: 1403/06/24 | E9: نیټه : | H9: ازموینه:نهايي | L9: استاد : عبدالعزیز حسنزی | P9: مضمون :سامان پیژندنه
A11: کتني | B11: مجموعه | D11: 60فیصده نمبری | E11: 20فیصده نمبری | F11: حاضری/صنفي | G11: پیژندنه | I11: ګڼه | J11: کتني | K11: مجموعه | M11: 60فیصده نمبری | N11: 20فیصده نمبری | O11: حاضری/صنفي | P11: پیژندنه | R11: ګڼه
B12: حروفی | C12: عددی | G12: د پلار نوم | H12: نوم | K12: حروفی | L12: عددی | P12: د پلار نوم | Q12: نوم
I13: 1 | K13: دوه اتیا | L13: =SUM(M13:O13) -> 82 | M13: 49 | N13: 13 | O13: 20 | P13: هدایت الله | Q13: نایب احمد | R13: 1
I14: 2 | K14: دوه نوي | L14: =SUM(M14:O14) -> 92 | M14: 56 | N14: 16 | O14: 20 | P14: حاجی نصیر | Q14: عازی | R14: 2
I15: 3 | K15: نهه نوي | L15: =SUM(M15:O15) -> 99 | M15: 59 | N15: 20 | O15: 20 | P15: محمدقلم | Q15: حضرت علی | R15: 3
I16: 4 | K16: شپږ نوي | L16: =SUM(M16:O16) -> 96 | M16: 56 | N16: 20 | O16: 20 | P16: خوانی | Q16: وحید الله | R16: 4
I17: 5 | K17: درې نوي | L17: =SUM(M17:O17) -> 93 | M17: 55 | N17: 18 | O17: 20 | P17: سربلند | Q17: نعمت الله | R17: 5
I18: 6 | K18: نهه اتیا | L18: =SUM(M18:O18) -> 89 | M18: 58 | N18: 11 | O18: 20 | P18: جلاد خان | Q18: ابراهیم | R18: 6
I19: 7 | K19: شپږ اویا | L19: =SUM(M19:O19) -> 76 | M19: 37 | N19: 19 | O19: 20 | P19: سیدالرحمن | Q19: مطیع الرحمن | R19: 7
I20: 8 | K20: شپږ نوي | L20: =SUM(M20:O20) -> 96 | M20: 60 | N20: 16 | O20: 20 | P20: صبرشاه | Q20: عمران خان | R20: 8
I21: 9 | K21: اتیا | L21: =SUM(M21:O21) -> 80 | M21: 55 | N21: 5 | O21: 20 | P21: سید مصیر | Q21: سیدحکمت الله | R21: 9
I22: 10 | K22: اتیا | L22: =SUM(M22:O22) -> 80 | M22: 54 | N22: 6 | O22: 20 | P22: هجرت الله | Q22: نصرت | R22: 10
I23: 11 | K23: پنځه نوي | L23: =SUM(M23:O23) -> 95 | M23: 57 | N23: 18 | O23: 20 | P23: محمد امین | Q23: سید امین | R23: 11
I24: 12 | K24: شپږ نوي | L24: =SUM(M24:O24) -> 96 | M24: 57 | N24: 19 | O24: 20 | P24: شمشیر | Q24: رحمن الله | R24: 12
... I30: 18 | K30: اتیا | L30: =SUM(M30:O30) -> 80 | M30: 40 | N30: 20 | O30: 20 | P30: فضل هادی | Q30: هلال | R30: 18
I31: 66 | R31: 24
I32: 67 | R32: 25
I33: 68 | R33: 26
I34: 69 | R34: 27
I35: 70 | R35: 28
I36: 71 | R36: 29
I37: 72 | R37: 30
I38: 73 | R38: 31
I39: 74 | R39: 32
I40: 75 | R40: 33
I41: 76 | R41: 34
A42: پورتنۍ نمبري د ازمویني له پرچو څخه له قلم خوری پرته شقي ته رسیدلي درست دي
E43: ممیزلاسلیک | M43: ممتحن لاسلیک

Sheet اختصاصي لابراتوار
A1: د عامی روغتیا وزارت
A2: د خصوصي روغتیايي علومو انستېتوتونو ریاست
A3: مومن د طبی علومو انستیتوت
A4: علمی او تحقیقاتی معاونیت
A5: تدریسي مدیریت
A6: ازموینو کمیټه
B7: چانس: لومړی | G7: وخت : ۹بجی | L7: سمستر:لومړی بهاری | P7: غاښونو پروتیز | Q7: څانګه :
A9: 1403/06/03 | E9: نیټه : | H9: ازموینه:نهايي | L9: استاد :عبدالعزیز حسنزی | P9: مضمون :اختصاصي لابراتوار
A11: کتني | B11: مجموعه | D11: 60فیصده نمبری | E11: 20فیصده نمبری | F11: حاضری/صنفي | G11: پیژندنه | I11: ګڼه | J11: کتني | K11: مجموعه | M11: 60فیصده نمبری | N11: 20فیصده نمبری | O11: حاضری/صنفي | P11: پیژندنه | R11: ګڼه
B12: حروفی | C12: عددی | G12: د پلار نوم | H12: نوم | K12: حروفی | L12: عددی | P12: د پلار نوم | Q12: نوم
I13: 1 | K13: اته اویا | L13: =SUM(M13:O13) -> 78 | M13: 43 | N13: 15 | O13: 20 | P13: هدایت الله | Q13: نایب احمد | R13: 1
I14: 2 | K14: اته اتیا | L14: =SUM(M14:O14) -> 88 | M14: 57 | N14: 11 | O14: 20 | P14: حاجی نصیر | Q14: عازی | R14: 2
I15: 3 | K15: پنځه شپېته | L15: =SUM(M15:O15) -> 65 | M15: 35 | N15: 10 | O15: 20 | P15: محمدقلم | Q15: حضرت علی | R15: 3
I16: 4 | K16: څلور اتیا | L16: =SUM(M16:O16) -> 84 | M16: 49 | N16: 15 | O16: 20 | P16: خوانی | Q16: وحید الله | R16: 4
I17: 5 | K17: څلور اویا | L17: =SUM(M17:O17) -> 74 | M17: 40 | N17: 14 | O17: 20 | P17: سربلند | Q17: نعمت الله | R17: 5
I18: 6 | K18: څلور نوي | L18: =SUM(M18:O18) -> 94 | M18: 57 | N18: 17 | O18: 20 | P18: جلاد خان | Q18: ابراهیم | R18: 6
I19: 7 | K19: سل | L19: =SUM(M19:O19) -> 100 | M19: 60 | N19: 20 | O19: 20 | P19: سیدالرحمن | Q19: مطیع الرحمن | R19: 7
I20: 8 | K20: یو اتیا | L20: =SUM(M20:O20) -> 81 | M20: 50 | N20: 11 | O20: 20 | P20: صبرشاه | Q20: عمران خان | R20: 8
I21: 9 | K21: یو نوي | L21: =SUM(M21:O21) -> 91 | M21: 51 | N21: 20 | O21: 20 | P21: سید مصیر | Q21: سیدحکمت الله | R21: 9
I22: 10 | K22: څلور اویا | L22: =SUM(M22:O22) -> 74 | M22: 38 | N22: 16 | O22: 20 | P22: هجرت الله | Q22: نصرت | R22: 10
I23: 11 | K23: درې نوي | L23: =SUM(M23:O23) -> 93 | M23: 53 | N23: 20 | O23: 20 | P23: محمد امین | Q23: سید امین | R23: 11
I24: 12 | K24: څلور اویا | L24: =SUM(M24:O24) -> 74 | M24: 37 | N24: 17 | O24: 20 | P24: شمشیر | Q24: رحمن الله | R24: 12
... I30: 18 | K30: نوي | L30: =SUM(M30:O30) -> 90 | M30: 59 | N30: 11 | O30: 20 | P30: فضل هادی | Q30: هلال | R30: 18
I31: 66 | L31: 0 | R31: 19
I32: 67 | L32: 0 | R32: 20
I33: 68 | R33: 21
I34: 69 | R34: 22
I35: 70 | R35: 23
I36: 71 | R36: 24
I37: 72 | R37: 25
I38: 73 | R38: 26
I39: 74 | R39: 27
I40: 75 | R40: 33
I41: 76 | R41: 34
A42: پورتنۍ نمبري د ازمویني له پرچو څخه له قلم خوری پرته شقي ته رسیدلي درست دي
E43: ممیزلاسلیک | M43: ممتحن لاسلیک

Sheet اختصاصي ترمینالوژی
A1: د عامی روغتیا وزارت
A2: د خصوصي روغتیايي علومو انستېتوتونو ریاست
A3: مومن د طبی علومو انستیتوت
A4: علمی او تحقیقاتی معاونیت
A5: تدریسي مدیریت
A6: ازموینو کمیټه
B7: چانس: لومړی | G7: وخت : ۹بجی | L7: سمستر:لومړی بهاری | P7: غاښونو پروتیز | Q7: څانګه :
A9: 1403/06/10 | E9: نیټه : | H9: ازموینه:نهايي | L9: استاد : عبدالعزیز حسنزی | P9: مضمون :اختصاصي ترمینالوژي
A11: کتني | B11: مجموعه | D11: 60فیصده نمبری | E11: 20فیصده نمبری | F11: حاضری/صنفي | G11: پیژندنه | I11: ګڼه | J11: کتني | K11: مجموعه | M11: 60فیصده نمبری | N11: 20فیصده نمبری | O11: حاضری/صنفي | P11: پیژندنه | R11: ګڼه
B12: حروفی | C12: عددی | G12: د پلار نوم | H12: نوم | K12: حروفی | L12: عددی | P12: د پلار نوم | Q12: نوم
I13: 1 | K13: نهه اتیا | L13: =SUM(M13:O13) -> 89 | M13: 49 | N13: 20 | O13: 20 | P13: هدایت الله | Q13: نایب احمد | R13: 1
I14: 2 | K14: درې نوي | L14: =SUM(M14:O14) -> 93 | M14: 54 | N14: 19 | O14: 20 | P14: حاجی نصیر | Q14: عازی | R14: 2
I15: 3 | K15: اویا | L15: =SUM(M15:O15) -> 70 | M15: 44 | N15: 6 | O15: 20 | P15: محمدقلم | Q15: حضرت علی | R15: 3
I16: 4 | K16: دوه نوي | L16: =SUM(M16:O16) -> 92 | M16: 52 | N16: 20 | O16: 20 | P16: خوانی | Q16: وحید الله | R16: 4
I17: 5 | K17: اته اتیا | L17: =SUM(M17:O17) -> 88 | M17: 48 | N17: 20 | O17: 20 | P17: سربلند | Q17: نعمت الله | R17: 5
I18: 6 | K18: اته نوي | L18: =SUM(M18:O18) -> 98 | M18: 59 | N18: 19 | O18: 20 | P18: جلاد خان | Q18: ابراهیم | R18: 6
I19: 7 | K19: پنځه اویا | L19: =SUM(M19:O19) -> 75 | M19: 38 | N19: 17 | O19: 20 | P19: سیدالرحمن | Q19: مطیع الرحمن | R19: 7
I20: 8 | K20: څلور نوي | L20: =SUM(M20:O20) -> 94 | M20: 58 | N20: 16 | O20: 20 | P20: صبرشاه | Q20: عمران خان | R20: 8
I21: 9 | K21: اوه نوي | L21: =SUM(M21:O21) -> 97 | M21: 60 | N21: 17 | O21: 20 | P21: سید مصیر | Q21: سیدحکمت الله | R21: 9
I22: 10 | K22: اته اویا | L22: =SUM(M22:O22) -> 78 | M22: 41 | N22: 17 | O22: 20 | P22: هجرت الله | Q22: نصرت | R22: 10
I23: 11 | K23: یو نوي | L23: =SUM(M23:O23) -> 91 | M23: 53 | N23: 18 | O23: 20 | P23: محمد امین | Q23: سید امین | R23: 11
I24: 12 | K24: نوي | L24: =SUM(M24:O24) -> 90 | M24: 53 | N24: 17 | O24: 20 | P24: شمشیر | Q24: رحمن الله | R24: 12
... I30: 18 | K30: شپږ اویا | L30: =SUM(M30:O30) -> 76 | M30: 46 | N30: 10 | O30: 20 | P30: فضل هادی | Q30: هلال | R30: 18
I31: 66 | R31: 19
I32: 67 | R32: 20
I33: 68 | R33: 21
I34: 69 | R34: 27
I35: 70 | R35: 28
I36: 71 | R36: 29
I37: 72 | R37: 30
I38: 73 | R38: 31
I39: 74 | R39: 32
I40: 75 | R40: 33
I41: 76 | R41: 34
A42: پورتنۍ نمبري د ازمویني له پرچو څخه له قلم خوری پرته شقي ته رسیدلي درست دي
E43: ممیزلاسلیک | M43: ممتحن لاسلیک

Sheet پتالوژی
A1: د عامی روغتیا وزارت
A2: د خصوصي روغتیايي علومو انستېتوتونو ریاست
A3: مومن د طبی علومو انستیتوت
A4: علمی او تحقیقاتی معاونیت
A5: تدریسي مدیریت
A6: ازموینو کمیټه
B7: چانس: لومړی | G7: وخت : ۹بجی | L7: سمستر:لومړی بهاری | P7: غاښونو پروتیز | Q7: څانګه :
A9: 1403/06/12 | E9: نیټه : | H9: ازموینه:نهايي | L9: استاد : رحمت الله عظیمي | P9: مضمون :پتالوژی
A11: کتني | B11: مجموعه | D11: 60فیصده نمبری | E11: 20فیصده نمبری | F11: حاضری/صنفي | G11: پیژندنه | I11: ګڼه | J11: کتني | K11: مجموعه | M11: 60فیصده نمبری | N11: 20فیصده نمبری | O11: حاضری/صنفي | P11: پیژندنه | R11: ګڼه
B12: حروفی | C12: عددی | G12: د پلار نوم | H12: نوم | K12: حروفی | L12: عددی | P12: د پلار نوم | Q12: نوم
I13: 1 | K13: څلور اویا | L13: =SUM(M13:O13) -> 74 | M13: 40 | N13: 14 | O13: 20 | P13: هدایت الله | Q13: نایب احمد | R13: 1
I14: 2 | K14: شپږ اتیا | L14: =SUM(M14:O14) -> 86 | M14: 53 | N14: 13 | O14: 20 | P14: حاجی نصیر | Q14: عازی | R14: 2
I15: 3 | K15: نوي | L15: =SUM(M15:O15) -> 90 | M15: 54 | N15: 16 | O15: 20 | P15: محمدقلم | Q15: حضرت علی | R15: 3
I16: 4 | K16: اته اتیا | L16: =SUM(M16:O16) -> 88 | M16: 52 | N16: 16 | O16: 20 | P16: خوانی | Q16: وحید الله | R16: 4
I17: 5 | K17: اته اتیا | L17: =SUM(M17:O17) -> 88 | M17: 59 | N17: 9 | O17: 20 | P17: سربلند | Q17: نعمت الله | R17: 5
I18: 6 | K18: یو اویا | L18: =SUM(M18:O18) -> 71 | M18: 31 | N18: 20 | O18: 20 | P18: جلاد خان | Q18: ابراهیم | R18: 6
I19: 7 | K19: درې اویا | L19: =SUM(M19:O19) -> 73 | M19: 48 | N19: 5 | O19: 20 | P19: سیدالرحمن | Q19: مطیع الرحمن | R19: 7
I20: 8 | K20: نهه اتیا | L20: =SUM(M20:O20) -> 89 | M20: 49 | N20: 20 | O20: 20 | P20: صبرشاه | Q20: عمران خان | R20: 8
I21: 9 | K21: اوه اویا | L21: =SUM(M21:O21) -> 77 | M21: 50 | N21: 7 | O21: 20 | P21: سید مصیر | Q21: سیدحکمت الله | R21: 9
I22: 10 | K22: اوه اتیا | L22: =SUM(M22:O22) -> 87 | M22: 55 | N22: 12 | O22: 20 | P22: هجرت الله | Q22: نصرت | R22: 10
I23: 11 | K23: دوه اویا | L23: =SUM(M23:O23) -> 72 | M23: 33 | N23: 19 | O23: 20 | P23: محمد امین | Q23: سید امین | R23: 11
I24: 12 | K24: څلور نوي | L24: =SUM(M24:O24) -> 94 | M24: 60 | N24: 14 | O24: 20 | P24: شمشیر | Q24: رحمن الله | R24: 12
... I30: 18 | K30: نهه نوي | L30: =SUM(M30:O30) -> 99 | M30: 59 | N30: 20 | O30: 20 | P30: فضل هادی | Q30: هلال | R30: 18
I31: 66 | R31: 19
I32: 67 | R32: 20
I33: 68 | R33: 21
I34: 69 | R34: 22
I35: 70 | R35: 23
I36: 71 | R36: 24
I37: 72 | R37: 25
I38: 73 | R38: 27
I39: 74 | R39: 28
I40: 75 | R40: 37
I41: 76 | R41: 38
A42: پورتنۍ نمبري د ازمویني له پرچو څخه له قلم خوری پرته شقي ته رسیدلي درست دي
E43: ممیزلاسلیک | M43: ممتحن لاسلیک

Sheet اناټومي فزیالوژی
A1: د عامی روغتیا وزارت
A2: د خصوصي روغتیايي علومو انستېتوتونو ریاست
A3: مومن د طبی علومو انستیتوت
A4: علمی او تحقیقاتی معاونیت
A5: تدریسي مدیریت
A6: ازموینو کمیټه
B7: چانس: لومړی | G7: وخت : ۹بجی | L7: سمستر:لومړی بهاری | P7: غاښونو پروتیز | Q7: څانګه :
A9: 1403/06/19 | E9: نیټه : | H9: ازموینه:نهايي | L9: استاد : اشرف زهیر | P9: مضمون :اناټومي فزیالوژی
A11: کتني | B11: مجموعه | D11: 60فیصده نمبری | E11: 20فیصده نمبری | F11: حاضری/صنفي | G11: پیژندنه | I11: ګڼه | J11: کتني | K11: مجموعه | M11: 60فیصده نمبری | N11: 20فیصده نمبری | O11: حاضری/صنفي | P11: پیژندنه | R11: ګڼه
B12: حروفی | C12: عددی | G12: د پلار نوم | H12: نوم | K12: حروفی | L12: عددی | P12: د پلار نوم | Q12: نوم
I13: 1 | K13: اویا | L13: =SUM(M13:O13) -> 70 | M13: 31 | N13: 19 | O13: 20 | P13: هدایت الله | Q13: نایب احمد | R13: 1
I14: 2 | K14: سل | L14: =SUM(M14:O14) -> 100 | M14: 60 | N14: 20 | O14: 20 | P14: حاجی نصیر | Q14: عازی | R14: 2
I15: 3 | K15: پنځه شپېته | L15: =SUM(M15:O15) -> 65 | M15: 40 | N15: 5 | O15: 20 | P15: محمدقلم | Q15: حضرت علی | R15: 3
I16: 4 | K16: نوي | L16: =SUM(M16:O16) -> 90 | M16: 52 | N16: 18 | O16: 20 | P16: خوانی | Q16: وحید الله | R16: 4
I17: 5 | K17: سل | L17: =SUM(M17:O17) -> 100 | M17: 60 | N17: 20 | O17: 20 | P17: سربلند | Q17: نعمت الله | R17: 5
I18: 6 | K18: دوه اتیا | L18: =SUM(M18:O18) -> 82 | M18: 44 | N18: 18 | O18: 20 | P18: جلاد خان | Q18: ابراهیم | R18: 6
I19: 7 | K19: درې اتیا | L19: =SUM(M19:O19) -> 83 | M19: 56 | N19: 7 | O19: 20 | P19: سیدالرحمن | Q19: مطیع الرحمن | R19: 7
I20: 8 | K20: سل | L20: =SUM(M20:O20) -> 100 | M20: 60 | N20: 20 | O20: 20 | P20: صبرشاه | Q20: عمران خان | R20: 8
I21: 9 | K21: اته اتیا | L21: =SUM(M21:O21) -> 88 | M21: 54 | N21: 14 | O21: 20 | P21: سید مصیر | Q21: سیدحکمت الله | R21: 9
I22: 10 | K22: یو اتیا | L22: =SUM(M22:O22) -> 81 | M22: 45 | N22: 16 | O22: 20 | P22: هجرت الله | Q22: نصرت | R22: 10
I23: 11 | K23: څلور اویا | L23: =SUM(M23:O23) -> 74 | M23: 49 | N23: 5 | O23: 20 | P23: محمد امین | Q23: سید امین | R23: 11
I24: 12 | K24: اته اتیا | L24: =SUM(M24:O24) -> 88 | M24: 49 | N24: 19 | O24: 20 | P24: شمشیر | Q24: رحمن الله | R24: 12
... I30: 18 | K30: دوه اتیا | L30: =SUM(M30:O30) -> 82 | M30: 54 | N30: 8 | O30: 20 | P30: فضل هادی | Q30: هلال | R30: 18
I31: 66 | R31: 28
I32: 67 | R32: 29
I33: 68 | R33: 30
I34: 69 | R34: 31
I35: 70 | R35: 32
I36: 71 | R36: 33
I37: 72 | R37: 34
I38: 73 | R38: 35
I39: 74 | R39: 36
I40: 75 | R40: 37
I41: 76 | R41: 38
A42: پورتنۍ نمبري د ازمویني له پرچو څخه له قلم خوری پرته شقي ته رسیدلي درست دي
E43: ممیزلاسلیک | M43: ممتحن لاسلیک

Sheet متحرک پروتیز
A1: د عامی روغتیا وزارت
A2: د خصوصي روغتیايي علومو انستېتوتونو ریاست
A3: مومن د طبی علومو انستیتوت
A4: علمی او تحقیقاتی معاونیت
A5: تدریسي مدیریت
A6: ازموینو کمیټه
B7: چانس: لومړی | G7: وخت : ۹بجی | L7: سمستر:لومړی بهاری | P7: غاښونو پروتیز | Q7: څانګه :
A9: 1403/06/21 | E9: نیټه : | H9: ازموینه:نهايي | L9: استاد : سید عبادالله سیدي | P9: مضمون :متحرک پروتیز
A11: کتني | B11: مجموعه | D11: 60فیصده نمبری | E11: 20فیصده نمبری | F11: حاضری/صنفي | G11: پیژندنه | I11: ګڼه | J11: کتني | K11: مجموعه | M11: 60فیصده نمبری | N11: 20فیصده نمبری | O11: حاضری/صنفي | P11: پیژندنه | R11: ګڼه
B12: حروفی | C12: عددی | G12: د پلار نوم | H12: نوم | K12: حروفی | L12: عددی | P12: د پلار نوم | Q12: نوم
I13: 1 | K13: اته اویا | L13: =SUM(M13:O13) -> 78 | M13: 51 | N13: 7 | O13: 20 | P13: هدایت الله | Q13: نایب احمد | R13: 1
I14: 2 | K14: درې اویا | L14: =SUM(M14:O14) -> 73 | M14: 37 | N14: 16 | O14: 20 | P14: حاجی نصیر | Q14: عازی | R14: 2
I15: 3 | K15: پنځه اتیا | L15: =SUM(M15:O15) -> 85 | M15: 51 | N15: 14 | O15: 20 | P15: محمدقلم | Q15: حضرت علی | R15: 3
I16: 4 | K16: څلور نوي | L16: =SUM(M16:O16) -> 94 | M16: 57 | N16: 17 | O16: 20 | P16: خوانی | Q16: وحید الله | R16: 4
I17: 5 | K17: نهه اتیا | L17: =SUM(M17:O17) -> 89 | M17: 50 | N17: 19 | O17: 20 | P17: سربلند | Q17: نعمت الله | R17: 5
I18: 6 | K18: پنځه نوي | L18: =SUM(M18:O18) -> 95 | M18: 58 | N18: 17 | O18: 20 | P18: جلاد خان | Q18: ابراهیم | R18: 6
I19: 7 | K19: شپږ اتیا | L19: =SUM(M19:O19) -> 86 | M19: 50 | N19: 16 | O19: 20 | P19: سیدالرحمن | Q19: مطیع الرحمن | R19: 7
I20: 8 | K20: څلور نوي | L20: =SUM(M20:O20) -> 94 | M20: 57 | N20: 17 | O20: 20 | P20: صبرشاه | Q20: عمران خان | R20: 8
I21: 9 | K21: نهه اتیا | L21: =SUM(M21:O21) -> 89 | M21: 56 | N21: 13 | O21: 20 | P21: سید مصیر | Q21: سیدحکمت الله | R21: 9
I22: 10 | K22: دوه اتیا | L22: =SUM(M22:O22) -> 82 | M22: 50 | N22: 12 | O22: 20 | P22: هجرت الله | Q22: نصرت | R22: 10
I23: 11 | K23: دوه اویا | L23: =SUM(M23:O23) -> 72 | M23: 38 | N23: 14 | O23: 20 | P23: محمد امین | Q23: سید امین | R23: 11
I24: 12 | K24: اوه اتیا | L24: =SUM(M24:O24) -> 87 | M24: 56 | N24: 11 | O24: 20 | P24: شمشیر | Q24: رحمن الله | R24: 12
... I30: 18 | K30: دوه نوي | L30: =SUM(M30:O30) -> 92 | M30: 58 | N30: 14 | O30: 20 | P30: فضل هادی | Q30: هلال | R30: 18
I31: 66 | L31: 0 | R31: 19
I32: 67 | R32: 29
I33: 68 | R33: 30
I34: 69 | R34: 31
I35: 70 | R35: 32
I36: 71 | R36: 33
I37: 72 | R37: 34
I38: 73 | R38: 35
I39: 74 | R39: 36
I40: 75 | R40: 37
I41: 76 | R41: 38
A42: پورتنۍ نمبري د ازمویني له پرچو څخه له قلم خوری پرته شقي ته رسیدلي درست دي
E43: ممیزلاسلیک | M43: ممتحن لاسلیک

Sheet مایکروبیولوژی
A1: د عامی روغتیا وزارت
A2: د خصوصي روغتیايي علومو انستېتوتونو ریاست
A3: مومن د طبی علومو انستیتوت
A4: علمی او تحقیقاتی معاونیت
A5: تدریسي مدیریت
A6: ازموینو کمیټه
B7: چانس: لومړی | G7: وخت : ۹بجی | L7: سمستر:لومړی بهاری | P7: غاښونو پروتیز | Q7: څانګه :
A9: 1403/06/05 | E9: نیټه : | H9: ازموینه:نهايي | L9: استاد : فرهاد ځلاند | P9: مضمون :مایکروبیولوژی
A11: کتني | B11: مجموعه | D11: 60فیصده نمبری | E11: 20فیصده نمبری | F11: حاضری/صنفي | G11: پیژندنه | I11: ګڼه | J11: کتني | K11: مجموعه | M11: 60فیصده نمبری | N11: 20فیصده نمبری | O11: حاضری/صنفي | P11: پیژندنه | R11: ګڼه
B12: حروفی | C12: عددی | G12: د پلار نوم | H12: نوم | K12: حروفی | L12: عددی | P12: د پلار نوم | Q12: نوم
I13: 1 | K13: څلور اتیا | L13: =SUM(M13:O13) -> 84 | M13: 46 | N13: 18 | O13: 20 | P13: هدایت الله | Q13: نایب احمد | R13: 1
I14: 2 | K14: درې نوي | L14: =SUM(M14:O14) -> 93 | M14: 57 | N14: 16 | O14: 20 | P14: حاجی نصیر | Q14: عازی | R14: 2
I15: 3 | K15: اوه اویا | L15: =SUM(M15:O15) -> 77 | M15: 37 | N15: 20 | O15: 20 | P15: محمدقلم | Q15: حضرت علی | R15: 3
I16: 4 | K16: پنځه نوي | L16: =SUM(M16:O16) -> 95 | M16: 57 | N16: 18 | O16: 20 | P16: خوانی | Q16: وحید الله | R16: 4
I17: 5 | K17: درې اتیا | L17: =SUM(M17:O17) -> 83 | M17: 44 | N17: 19 | O17: 20 | P17: سربلند | Q17: نعمت الله | R17: 5
I18: 6 | K18: دوه نوي | L18: =SUM(M18:O18) -> 92 | M18: 56 | N18: 16 | O18: 20 | P18: جلاد خان | Q18: ابراهیم | R18: 6
I19: 7 | K19: درې اویا | L19: =SUM(M19:O19) -> 73 | M19: 34 | N19: 19 | O19: 20 | P19: سیدالرحمن | Q19: مطیع الرحمن | R19: 7
I20: 8 | K20: پنځه نوي | L20: =SUM(M20:O20) -> 95 | M20: 59 | N20: 16 | O20: 20 | P20: صبرشاه | Q20: عمران خان | R20: 8
I21: 9 | K21: اته اویا | L21: =SUM(M21:O21) -> 78 | M21: 51 | N21: 7 | O21: 20 | P21: سید مصیر | Q21: سیدحکمت الله | R21: 9
I22: 10 | K22: پنځه اتیا | L22: =SUM(M22:O22) -> 85 | M22: 58 | N22: 7 | O22: 20 | P22: هجرت الله | Q22: نصرت | R22: 10
I23: 11 | K23: دوه نوي | L23: =SUM(M23:O23) -> 92 | M23: 56 | N23: 16 | O23: 20 | P23: محمد امین | Q23: سید امین | R23: 11
I24: 12 | K24: شپږ اتیا | L24: =SUM(M24:O24) -> 86 | M24: 47 | N24: 19 | O24: 20 | P24: شمشیر | Q24: رحمن الله | R24: 12
... I30: 18 | K30: دوه نوي | L30: =SUM(M30:O30) -> 92 | M30: 55 | N30: 17 | O30: 20 | P30: فضل هادی | Q30: هلال | R30: 18
I31: 66 | R31: 19
I32: 67 | R32: 20
I33: 68 | R33: 21
I34: 69 | R34: 22
I35: 70 | R35: 23
I36: 71 | R36: 33
I37: 72 | R37: 34
I38: 73 | R38: 35
I39: 74 | R39: 36
I40: 75 | R40: 37
I41: 76 | R41: 38
A42: پورتنۍ نمبري د ازمویني له پرچو څخه له قلم خوری پرته شقي ته رسیدلي درست دي
E43: ممیزلاسلیک | M43: ممتحن لاسلیک

Sheet PHC
A1: د عامی روغتیا وزارت
A2: د خصوصي روغتیايي علومو انستېتوتونو ریاست
A3: مومن د طبی علومو انستیتوت
A4: علمی او تحقیقاتی معاونیت
A5: تدریسي مدیریت
A6: ازموینو کمیټه
B7: چانس: لومړی | G7: وخت : ۹بجی | L7: سمستر:لومړی بهاری | P7: غاښونو پروتیز | Q7: څانګه :
A9: 1403/06/24 | E9: نیټه : | H9: ازموینه:نهايي | L9: استاد : سید عباد الله سیدي | P9: مضمون :PHC
A11: کتني | B11: مجموعه | D11: 60فیصده نمبری | E11: 20فیصده نمبری | F11: حاضری/صنفي | G11: پیژندنه | I11: ګڼه | J11: کتني | K11: مجموعه | M11: 60فیصده نمبری | N11: 20فیصده نمبری | O11: حاضری/صنفي | P11: پیژندنه | R11: ګڼه
B12: حروفی | C12: عددی | G12: د پلار نوم | H12: نوم | K12: حروفی | L12: عددی | P12: د پلار نوم | Q12: نوم
I13: 1 | K13: پنځه اتیا | L13: =SUM(M13:O13) -> 85 | M13: 60 | N13: 5 | O13: 20 | P13: هدایت الله | Q13: نایب احمد | R13: 1
I14: 2 | K14: نهه اتیا | L14: =SUM(M14:O14) -> 89 | M14: 57 | N14: 12 | O14: 20 | P14: حاجی نصیر | Q14: عازی | R14: 2
I15: 3 | K15: پنځه اتیا | L15: =SUM(M15:O15) -> 85 | M15: 48 | N15: 17 | O15: 20 | P15: محمدقلم | Q15: حضرت علی | R15: 3
I16: 4 | K16: پنځه نوي | L16: =SUM(M16:O16) -> 95 | M16: 57 | N16: 18 | O16: 20 | P16: خوانی | Q16: وحید الله | R16: 4
I17: 5 | K17: درې نوي | L17: =SUM(M17:O17) -> 93 | M17: 60 | N17: 13 | O17: 20 | P17: سربلند | Q17: نعمت الله | R17: 5
I18: 6 | K18: اته اتیا | L18: =SUM(M18:O18) -> 88 | M18: 49 | N18: 19 | O18: 20 | P18: جلاد خان | Q18: ابراهیم | R18: 6
I19: 7 | K19: دوه نوي | L19: =SUM(M19:O19) -> 92 | M19: 60 | N19: 12 | O19: 20 | P19: سیدالرحمن | Q19: مطیع الرحمن | R19: 7
I20: 8 | K20: درې نوي | L20: =SUM(M20:O20) -> 93 | M20: 57 | N20: 16 | O20: 20 | P20: صبرشاه | Q20: عمران خان | R20: 8
I21: 9 | K21: پنځه نوي | L21: =SUM(M21:O21) -> 95 | M21: 55 | N21: 20 | O21: 20 | P21: سید مصیر | Q21: سیدحکمت الله | R21: 9
I22: 10 | K22: شپږ اتیا | L22: =SUM(M22:O22) -> 86 | M22: 49 | N22: 17 | O22: 20 | P22: هجرت الله | Q22: نصرت | R22: 10
I23: 11 | K23: نوي | L23: =SUM(M23:O23) -> 90 | M23: 54 | N23: 16 | O23: 20 | P23: محمد امین | Q23: سید امین | R23: 11
I24: 12 | K24: اوه اویا | L24: =SUM(M24:O24) -> 77 | M24: 51 | N24: 6 | O24: 20 | P24: شمشیر | Q24: رحمن الله | R24: 12
... I30: 18 | K30: څلور نوي | L30: =SUM(M30:O30) -> 94 | M30: 57 | N30: 17 | O30: 20 | P30: فضل هادی | Q30: هلال | R30: 18
I31: 66 | R31: 28
I32: 67 | R32: 29
I33: 68 | R33: 30
I34: 69 | R34: 31
I35: 70 | R35: 32
I36: 71 | R36: 33
I37: 72 | R37: 34
I38: 73 | R38: 35
I39: 74 | R39: 36
I40: 75 | R40: 37
I41: 76 | R41: 38
A42: پورتنۍ نمبري د ازمویني له پرچو څخه له قلم خوری پرته شقي ته رسیدلي درست دي
E43: ممیزلاسلیک | M43: ممتحن لاسلیک

Sheet نتایج
A1: پلارم نوم | B1: نوم
A2: هدایت الله | B2: نایب احمد
A3: حاجی نصیر | B3: عازی
A4: محمدقلم | B4: حضرت علی
A5: خوانی | B5: وحید الله
A6: سربلند | B6: نعمت الله
A7: جلاد خان | B7: ابراهیم
A8: سیدالرحمن | B8: مطیع الرحمن
A9: صبرشاه | B9: عمران خان
A10: سید مصیر | B10: سیدحکمت الله
A11: هجرت الله | B11: نصرت
A12: محمد امین | B12: سید امین
... A19: فضل هادی | B19: هلال

Sheet فلتر شوی
A1: د عامی روغتیا وزارت
A2: د خصوصي روغتیايي علومو انستېتوتونو ریاست
A3: مومن د طبی علومو انستیتوت
A4: علمی او تحقیقاتی معاونیت
A5: ازموینی کمیټه
A7: د روان ۱۴۰۳ هـ ش کال د غاښونو پروتیز لومړی ټولګی لومړی سمستر سهار ( ۹ ) بجی دوره د نتایجو او نمراتو د تعین جدول
A8: درجه | B8: نتیجه | C8: نمبري | E8: مضامین | Q8: پیژندنه | S8: عمومی ګڼه
C9: فیصدی | D9: په عدد | E9: PHC | F9: مایکروبیولوژی | G9: متحرک پروتیز | H9: اناټومی فزیالوژی | I9: پتالوژی | J9: اختصاصی ترمینالوژی | K9: اختصاصی لابراتوار | L9: سامان پیژندنه | M9: مورفولوژی | N9: طبی انګلیسی | O9: عمومی ترمینالوژی | P9: اسلامیات | Q9: پلارم نوم | R9: نوم
C11: =D11/12 -> #REF! | D11: =SUM(E11:P11) -> #REF! | E11: =PHC!#REF! -> #REF! | F11: =مایکروبیولوژی!#REF! -> #REF! | G11: ='متحرک پروتیز'!#REF! -> #REF! | H11: ='اناټومي فزیالوژی'!#REF! -> #REF! | I11: =پتالوژی!#REF! -> #REF! | J11: ='اختصاصي ترمینالوژی'!#REF! -> #REF! | K11: ='اختصاصي لابراتوار'!#REF! -> #REF! | L11: ='سامان پیژندنه'!#REF! -> #REF! | M11: =مورفولوژی!#REF! -> #REF! | N11: ='طبي انګلیسي'!#REF! -> #REF! | O11: ='عمومي ترمینالوژی'!#REF! -> #REF! | P11: =اسلامیات!#REF! -> #REF! | Q11: محمد رفیق | R11: ماریه | S11: 1
C12: =D12/12 -> 94.5 | D12: =SUM(E12:P12) -> 1134 | E12: =PHC!L25 -> 97 | F12: =مایکروبیولوژی!L25 -> 85 | G12: ='متحرک پروتیز'!L25 -> 97 | H12: ='اناټومي فزیالوژی'!L25 -> 100 | I12: =پتالوژی!L25 -> 98 | J12: ='اختصاصي ترمینالوژی'!L25 -> 94 | K12: ='اختصاصي لابراتوار'!L25 -> 83 | L12: ='سامان پیژندنه'!L25 -> 96 | M12: =مورفولوژی!L25 -> 95 | N12: ='طبي انګلیسي'!L25 -> 98 | O12: ='عمومي ترمینالوژی'!L25 -> 100 | P12: =اسلامیات!L25 -> 91 | Q12: عیاث الدین | R12: نثار احمد | S12: 2
C13: =D13/12 -> 93 | D13: =SUM(E13:P13) -> 1116 | E13: =PHC!L16 -> 95 | F13: =مایکروبیولوژی!L16 -> 95 | G13: ='متحرک پروتیز'!L16 -> 94 | H13: ='اناټومي فزیالوژی'!L16 -> 90 | I13: =پتالوژی!L16 -> 88 | J13: ='اختصاصي ترمینالوژی'!L16 -> 92 | K13: ='اختصاصي لابراتوار'!L16 -> 84 | L13: ='سامان پیژندنه'!L16 -> 96 | M13: =مورفولوژی!L16 -> 89 | N13: ='طبي انګلیسي'!L16 -> 98 | O13: ='عمومي ترمینالوژی'!L16 -> 100 | P13: =اسلامیات!L16 -> 95 | Q13: خوانی | R13: وحید الله | S13: 3
C14: =D14/12 -> 92.333333 | D14: =SUM(E14:P14) -> 1108 | E14: =PHC!L20 -> 93 | F14: =مایکروبیولوژی!L20 -> 95 | G14: ='متحرک پروتیز'!L20 -> 94 | H14: ='اناټومي فزیالوژی'!L20 -> 100 | I14: =پتالوژی!L20 -> 89 | J14: ='اختصاصي ترمینالوژی'!L20 -> 94 | K14: ='اختصاصي لابراتوار'!L20 -> 81 | L14: ='سامان پیژندنه'!L20 -> 96 | M14: =مورفولوژی!L20 -> 92 | N14: ='طبي انګلیسي'!L20 -> 90 | O14: ='عمومي ترمینالوژی'!L20 -> 90 | P14: =اسلامیات!L20 -> 94 | Q14: صبرشاه | R14: عمران خان | S14: 4
C15: =D15/12 -> 89.5 | D15: =SUM(E15:P15) -> 1074 | E15: =PHC!L17 -> 93 | F15: =مایکروبیولوژی!L17 -> 83 | G15: ='متحرک پروتیز'!L17 -> 89 | H15: ='اناټومي فزیالوژی'!L17 -> 100 | I15: =پتالوژی!L17 -> 88 | J15: ='اختصاصي ترمینالوژی'!L17 -> 88 | K15: ='اختصاصي لابراتوار'!L17 -> 74 | L15: ='سامان پیژندنه'!L17 -> 93 | M15: =مورفولوژی!L17 -> 96 | N15: ='طبي انګلیسي'!L17 -> 90 | O15: ='عمومي ترمینالوژی'!L17 -> 92 | P15: =اسلامیات!L17 -> 88 | Q15: سربلند | R15: نعمت الله | S15: 5
C16: =D16/12 -> #REF! | D16: =SUM(E16:P16) -> #REF! | E16: =PHC!#REF! -> #REF! | F16: =مایکروبیولوژی!#REF! -> #REF! | G16: ='متحرک پروتیز'!#REF! -> #REF! | H16: ='اناټومي فزیالوژی'!#REF! -> #REF! | I16: =پتالوژی!#REF! -> #REF! | J16: ='اختصاصي ترمینالوژی'!#REF! -> #REF! | K16: ='اختصاصي لابراتوار'!#REF! -> #REF! | L16: ='سامان پیژندنه'!#REF! -> #REF! | M16: =مورفولوژی!#REF! -> #REF! | N16: ='طبي انګلیسي'!#REF! -> #REF! | O16: ='عمومي ترمینالوژی'!#REF! -> #REF! | P16: =اسلامیات!#REF! -> #REF! | Q16: عبدالحمید | R16: لیمه | S16: 6
C17: =D17/12 -> 83.916667 | D17: =SUM(E17:P17) -> 1007 | E17: =PHC!L26 -> 85 | F17: =مایکروبیولوژی!L26 -> 87 | G17: ='متحرک پروتیز'!L26 -> 93 | H17: ='اناټومي فزیالوژی'!L26 -> 83 | I17: =پتالوژی!L26 -> 86 | J17: ='اختصاصي ترمینالوژی'!L26 -> 85 | K17: ='اختصاصي لابراتوار'!L26 -> 71 | L17: ='سامان پیژندنه'!L26 -> 82 | M17: =مورفولوژی!L26 -> 95 | N17: ='طبي انګلیسي'!L26 -> 70 | O17: ='عمومي ترمینالوژی'!L26 -> 88 | P17: =اسلامیات!L26 -> 82 | Q17: امر الله | R17: حنیف الله | S17: 7
C18: =D18/12 -> 74.833333 | D18: =SUM(E18:P18) -> 898 | E18: =PHC!L28 -> 85 | F18: =مایکروبیولوژی!L28 -> 80 | G18: ='متحرک پروتیز'!L28 -> 80 | H18: ='اناټومي فزیالوژی'!L28 -> 72 | I18: =پتالوژی!L28 -> 64 | J18: ='اختصاصي ترمینالوژی'!L28 -> 85 | K18: ='اختصاصي لابراتوار'!L28 -> 60 | L18: ='سامان پیژندنه'!L28 -> 84 | M18: =مورفولوژی!L28 -> 68 | N18: ='طبي انګلیسي'!L28 -> 70 | O18: ='عمومي ترمینالوژی'!L28 -> 70 | P18: =اسلامیات!L28 -> 80 | Q18: سلطان شاه | R18: شوکت الله | S18: 8
C19: =D19/12 -> 78.5 | D19: =SUM(E19:P19) -> 942 | E19: =PHC!L15 -> 85 | F19: =مایکروبیولوژی!L15 -> 77 | G19: ='متحرک پروتیز'!L15 -> 85 | H19: ='اناټومي فزیالوژی'!L15 -> 65 | I19: =پتالوژی!L15 -> 90 | J19: ='اختصاصي ترمینالوژی'!L15 -> 70 | K19: ='اختصاصي لابراتوار'!L15 -> 65 | L19: ='سامان پیژندنه'!L15 -> 99 | M19: =مورفولوژی!L15 -> 56 | N19: ='طبي انګلیسي'!L15 -> 98 | O19: ='عمومي ترمینالوژی'!L15 -> 60 | P19: =اسلامیات!L15 -> 92 | Q19: محمدقلم | R19: حضرت علی | S19: 9
C20: =D20/12 -> #REF! | D20: =SUM(E20:P20) -> #REF! | E20: =PHC!#REF! -> #REF! | F20: =مایکروبیولوژی!#REF! -> #REF! | G20: ='متحرک پروتیز'!#REF! -> #REF! | H20: ='اناټومي فزیالوژی'!#REF! -> #REF! | I20: =پتالوژی!#REF! -> #REF! | J20: ='اختصاصي ترمینالوژی'!#REF! -> #REF! | K20: ='اختصاصي لابراتوار'!#REF! -> #REF! | L20: ='سامان پیژندنه'!#REF! -> #REF! | M20: =مورفولوژی!#REF! -> #REF! | N20: ='طبي انګلیسي'!#REF! -> #REF! | O20: ='عمومي ترمینالوژی'!#REF! -> #REF! | P20: =اسلامیات!#REF! -> #REF! | Q20: محمد قلم | R20: حضرت علی | S20: 10
C21: =D21/12 -> #REF! | D21: =SUM(E21:P21) -> #REF! | E21: =PHC!#REF! -> #REF! | F21: =مایکروبیولوژی!#REF! -> #REF! | G21: ='متحرک پروتیز'!#REF! -> #REF! | H21: ='اناټومي فزیالوژی'!#REF! -> #REF! | I21: =پتالوژی!#REF! -> #REF! | J21: ='اختصاصي ترمینالوژی'!#REF! -> #REF! | K21: ='اختصاصي لابراتوار'!#REF! -> #REF! | L21: ='سامان پیژندنه'!#REF! -> #REF! | M21: =مورفولوژی!#REF! -> #REF! | N21: ='طبي انګلیسي'!#REF! -> #REF! | O21: ='عمومي ترمینالوژی'!#REF! -> #REF! | P21: =اسلامیات!#REF! -> #REF! | Q21: سلطان شاه | R21: شوکت الله | S21: 11
C22: =D22/12 -> 85.5 | D22: =SUM(E22:P22) -> 1026 | E22: =PHC!L18 -> 88 | F22: =مایکروبیولوژی!L18 -> 92 | G22: ='متحرک پروتیز'!L18 -> 95 | H22: ='اناټومي فزیالوژی'!L18 -> 82 | I22: =پتالوژی!L18 -> 71 | J22: ='اختصاصي ترمینالوژی'!L18 -> 98 | K22: ='اختصاصي لابراتوار'!L18 -> 94 | L22: ='سامان پیژندنه'!L18 -> 89 | M22: =مورفولوژی!L18 -> 82 | N22: ='طبي انګلیسي'!L18 -> 60 | O22: ='عمومي ترمینالوژی'!L18 -> 88 | P22: =اسلامیات!L18 -> 87 | Q22: جلاد خان | R22: ابراهیم | S22: 12
C23: =D23/12 -> 81.666667 | D23: =SUM(E23:P23) -> 980 | E23: =PHC!L13 -> 85 | F23: =مایکروبیولوژی!L13 -> 84 | G23: ='متحرک پروتیز'!L13 -> 78 | H23: ='اناټومي فزیالوژی'!L13 -> 70 | I23: =پتالوژی!L13 -> 74 | J23: ='اختصاصي ترمینالوژی'!L13 -> 89 | K23: ='اختصاصي لابراتوار'!L13 -> 78 | L23: ='سامان پیژندنه'!L13 -> 82 | M23: =مورفولوژی!L13 -> 86 | N23: ='طبي انګلیسي'!L13 -> 83 | O23: ='عمومي ترمینالوژی'!L13 -> 91 | P23: =اسلامیات!L13 -> 80 | Q23: هدایت الله | R23: نایب احمد | S23: 13
C24: =D24/12 -> 85.916667 | D24: =SUM(E24:P24) -> 1031 | E24: =PHC!L14 -> 89 | F24: =مایکروبیولوژی!L14 -> 93 | G24: ='متحرک پروتیز'!L14 -> 73 | H24: ='اناټومي فزیالوژی'!L14 -> 100 | I24: =پتالوژی!L14 -> 86 | J24: ='اختصاصي ترمینالوژی'!L14 -> 93 | K24: ='اختصاصي لابراتوار'!L14 -> 88 | L24: ='سامان پیژندنه'!L14 -> 92 | M24: =مورفولوژی!L14 -> 84 | N24: ='طبي انګلیسي'!L14 -> 77 | O24: ='عمومي ترمینالوژی'!L14 -> 76 | P24: =اسلامیات!L14 -> 80 | Q24: حاجی نصیر | R24: عازی | S24: 14
C25: =D25/12 -> 83.083333 | D25: =SUM(E25:P25) -> 997 | E25: =PHC!L19 -> 92 | F25: =مایکروبیولوژی!L19 -> 73 | G25: ='متحرک پروتیز'!L19 -> 86 | H25: ='اناټومي فزیالوژی'!L19 -> 83 | I25: =پتالوژی!L19 -> 73 | J25: ='اختصاصي ترمینالوژی'!L19 -> 75 | K25: ='اختصاصي لابراتوار'!L19 -> 100 | L25: ='سامان پیژندنه'!L19 -> 76 | M25: =مورفولوژی!L19 -> 99 | N25: ='طبي انګلیسي'!L19 -> 85 | O25: ='عمومي ترمینالوژی'!L19 -> 80 | P25: =اسلامیات!L19 -> 75 | Q25: سیدالرحمن | R25: مطیع الرحمن | S25: 15
C26: =D26/12 -> 86.916667 | D26: =SUM(E26:P26) -> 1043 | E26: =PHC!L21 -> 95 | F26: =مایکروبیولوژی!L21 -> 78 | G26: ='متحرک پروتیز'!L21 -> 89 | H26: ='اناټومي فزیالوژی'!L21 -> 88 | I26: =پتالوژی!L21 -> 77 | J26: ='اختصاصي ترمینالوژی'!L21 -> 97 | K26: ='اختصاصي لابراتوار'!L21 -> 91 | L26: ='سامان پیژندنه'!L21 -> 80 | M26: =مورفولوژی!L21 -> 78 | N26: ='طبي انګلیسي'!L21 -> 84 | O26: ='عمومي ترمینالوژی'!L21 -> 100 | P26: =اسلامیات!L21 -> 86 | Q26: سید مصیر | R26: سیدحکمت الله | S26: 16
C27: =D27/12 -> 80 | D27: =SUM(E27:P27) -> 960 | E27: =PHC!L22 -> 86 | F27: =مایکروبیولوژی!L22 -> 85 | G27: ='متحرک پروتیز'!L22 -> 82 | H27: ='اناټومي فزیالوژی'!L22 -> 81 | I27: =پتالوژی!L22 -> 87 | J27: ='اختصاصي ترمینالوژی'!L22 -> 78 | K27: ='اختصاصي لابراتوار'!L22 -> 74 | L27: ='سامان پیژندنه'!L22 -> 80 | M27: =مورفولوژی!L22 -> 80 | N27: ='طبي انګلیسي'!L22 -> 80 | O27: ='عمومي ترمینالوژی'!L22 -> 77 | P27: =اسلامیات!L22 -> 70 | Q27: هجرت الله | R27: نصرت | S27: 17
C28: =D28/12 -> 85.5 | D28: =SUM(E28:P28) -> 1026 | E28: =PHC!L23 -> 90 | F28: =مایکروبیولوژی!L23 -> 92 | G28: ='متحرک پروتیز'!L23 -> 72 | H28: ='اناټومي فزیالوژی'!L23 -> 74 | I28: =پتالوژی!L23 -> 72 | J28: ='اختصاصي ترمینالوژی'!L23 -> 91 | K28: ='اختصاصي لابراتوار'!L23 -> 93 | L28: ='سامان پیژندنه'!L23 -> 95 | M28: =مورفولوژی!L23 -> 93 | N28: ='طبي انګلیسي'!L23 -> 100 | O28: ='عمومي ترمینالوژی'!L23 -> 84 | P28: =اسلامیات!L23 -> 70 | Q28: محمد امین | R28: سید امین | S28: 18
C29: =D29/12 -> 85.583333 | D29: =SUM(E29:P29) -> 1027 | E29: =PHC!L24 -> 77 | F29: =مایکروبیولوژی!L24 -> 86 | G29: ='متحرک پروتیز'!L24 -> 87 | H29: ='اناټومي فزیالوژی'!L24 -> 88 | I29: =پتالوژی!L24 -> 94 | J29: ='اختصاصي ترمینالوژی'!L24 -> 90 | K29: ='اختصاصي لابراتوار'!L24 -> 74 | L29: ='سامان پیژندنه'!L24 -> 96 | M29: =مورفولوژی!L24 -> 82 | N29: ='طبي انګلیسي'!L24 -> 85 | O29: ='عمومي ترمینالوژی'!L24 -> 74 | P29: =اسلامیات!L24 -> 94 | Q29: شمشیر | R29: رحمن الله | S29: 19
C30: =D30/12 -> #REF! | D30: =SUM(E30:P30) -> #REF! | E30: =PHC!#REF! -> #REF! | F30: =مایکروبیولوژی!#REF! -> #REF! | G30: ='متحرک پروتیز'!#REF! -> #REF! | H30: ='اناټومي فزیالوژی'!#REF! -> #REF! | I30: =پتالوژی!#REF! -> #REF! | J30: ='اختصاصي ترمینالوژی'!#REF! -> #REF! | K30: ='اختصاصي لابراتوار'!#REF! -> #REF! | L30: ='سامان پیژندنه'!#REF! -> #REF! | M30: =مورفولوژی!#REF! -> #REF! | N30: ='طبي انګلیسي'!#REF! -> #REF! | O30: ='عمومي ترمینالوژی'!#REF! -> #REF! | P30: =اسلامیات!#REF! -> #REF! | Q30: سید بصیر | R30: بی بی سوما | S30: 20
C31: =D31/12 -> 88.25 | D31: =SUM(E31:P31) -> 1059 | E31: =PHC!L27 -> 84 | F31: =مایکروبیولوژی!L27 -> 84 | G31: ='متحرک پروتیز'!L27 -> 80 | H31: ='اناټومي فزیالوژی'!L27 -> 98 | I31: =پتالوژی!L27 -> 100 | J31: ='اختصاصي ترمینالوژی'!L27 -> 93 | K31: ='اختصاصي لابراتوار'!L27 -> 78 | L31: ='سامان پیژندنه'!L27 -> 90 | M31: =مورفولوژی!L27 -> 94 | N31: ='طبي انګلیسي'!L27 -> 99 | O31: ='عمومي ترمینالوژی'!L27 -> 86 | P31: =اسلامیات!L27 -> 73 | Q31: هجرت الله | R31: زبیر الله | S31: 21
C32: =D32/12 -> #REF! | D32: =SUM(E32:P32) -> #REF! | E32: =PHC!#REF! -> #REF! | F32: =مایکروبیولوژی!#REF! -> #REF! | G32: ='متحرک پروتیز'!#REF! -> #REF! | H32: ='اناټومي فزیالوژی'!#REF! -> #REF! | I32: =پتالوژی!#REF! -> #REF! | J32: ='اختصاصي ترمینالوژی'!#REF! -> #REF! | K32: ='اختصاصي لابراتوار'!#REF! -> #REF! | L32: ='سامان پیژندنه'!#REF! -> #REF! | M32: =مورفولوژی!#REF! -> #REF! | N32: ='طبي انګلیسي'!#REF! -> #REF! | O32: ='عمومي ترمینالوژی'!#REF! -> #REF! | P32: =اسلامیات!#REF! -> #REF! | Q32: عارف | R32: ثناء | S32: 22
C33: =D33/12 -> 84.166667 | D33: =SUM(E33:P33) -> 1010 | E33: =PHC!L29 -> 88 | F33: =مایکروبیولوژی!L29 -> 83 | G33: ='متحرک پروتیز'!L29 -> 75 | H33: ='اناټومي فزیالوژی'!L29 -> 94 | I33: =پتالوژی!L29 -> 76 | J33: ='اختصاصي ترمینالوژی'!L29 -> 78 | K33: ='اختصاصي لابراتوار'!L29 -> 93 | L33: ='سامان پیژندنه'!L29 -> 84 | M33: =مورفولوژی!L29 -> 79 | N33: ='طبي انګلیسي'!L29 -> 92 | O33: ='عمومي ترمینالوژی'!L29 -> 80 | P33: =اسلامیات!L29 -> 88 | Q33: وارث خان | R33: تحسین الله | S33: 23
C34: =D34/12 -> 88.416667 | D34: =SUM(E34:P34) -> 1061 | E34: =PHC!L30 -> 94 | F34: =مایکروبیولوژی!L30 -> 92 | G34: ='متحرک پروتیز'!L30 -> 92 | H34: ='اناټومي فزیالوژی'!L30 -> 82 | I34: =پتالوژی!L30 -> 99 | J34: ='اختصاصي ترمینالوژی'!L30 -> 76 | K34: ='اختصاصي لابراتوار'!L30 -> 90 | L34: ='سامان پیژندنه'!L30 -> 80 | M34: =مورفولوژی!L30 -> 86 | N34: ='طبي انګلیسي'!L30 -> 99 | O34: ='عمومي ترمینالوژی'!L30 -> 84 | P34: =اسلامیات!L30 -> 87 | Q34: فضل هادی | R34: هلال | S34: 24
C35: =D35/12 -> #REF! | D35: =SUM(E35:P35) -> #REF! | E35: =PHC!#REF! -> #REF! | F35: =مایکروبیولوژی!#REF! -> #REF! | G35: ='متحرک پروتیز'!#REF! -> #REF! | H35: ='اناټومي فزیالوژی'!#REF! -> #REF! | I35: =پتالوژی!#REF! -> #REF! | J35: ='اختصاصي ترمینالوژی'!#REF! -> #REF! | K35: ='اختصاصي لابراتوار'!#REF! -> #REF! | L35: ='سامان پیژندنه'!#REF! -> #REF! | M35: =مورفولوژی!#REF! -> #REF! | N35: ='طبي انګلیسي'!#REF! -> #REF! | O35: ='عمومي ترمینالوژی'!#REF! -> #REF! | P35: =اسلامیات!#REF! -> #REF! | Q35: وارث خان | R35: تحسن الله | S35: 25
C36: =D36/12 -> #REF! | D36: =SUM(E36:P36) -> #REF! | E36: =PHC!#REF! -> #REF! | F36: =مایکروبیولوژی!#REF! -> #REF! | G36: ='متحرک پروتیز'!#REF! -> #REF! | H36: ='اناټومي فزیالوژی'!#REF! -> #REF! | I36: =پتالوژی!#REF! -> #REF! | J36: ='اختصاصي ترمینالوژی'!#REF! -> #REF! | K36: ='اختصاصي لابراتوار'!#REF! -> #REF! | L36: ='سامان پیژندنه'!#REF! -> #REF! | M36: =مورفولوژی!#REF! -> #REF! | N36: ='طبي انګلیسي'!#REF! -> #REF! | O36: ='عمومي ترمینالوژی'!#REF! -> #REF! | P36: =اسلامیات!#REF! -> #REF! | Q36: فضل هادی | R36: هلال | S36: 26
C37: =D37/12 -> #REF! | D37: =SUM(E37:P37) -> #REF! | E37: =PHC!#REF! -> #REF! | F37: =مایکروبیولوژی!#REF! -> #REF! | G37: ='متحرک پروتیز'!#REF! -> #REF! | H37: ='اناټومي فزیالوژی'!#REF! -> #REF! | I37: =پتالوژی!#REF! -> #REF! | J37: ='اختصاصي ترمینالوژی'!#REF! -> #REF! | K37: ='اختصاصي لابراتوار'!#REF! -> #REF! | L37: ='سامان پیژندنه'!#REF! -> #REF! | M37: =مورفولوژی!#REF! -> #REF! | N37: ='طبي انګلیسي'!#REF! -> #REF! | O37: ='عمومي ترمینالوژی'!#REF! -> #REF! | P37: =اسلامیات!#REF! -> #REF! | Q37: عبدالحلیم | R37: فضیله | S37: 27
C38: =D38/12 -> 0 | D38: =SUM(E38:P38) -> 0 | E38: =PHC!L31 -> 0 | F38: =مایکروبیولوژی!L31 -> 0 | G38: ='متحرک پروتیز'!L31 -> 0 | H38: ='اناټومي فزیالوژی'!L31 -> 0 | I38: =پتالوژی!L31 -> 0 | J38: ='اختصاصي ترمینالوژی'!L31 -> 0 | K38: ='اختصاصي لابراتوار'!L31 -> 0 | L38: ='سامان پیژندنه'!L31 -> 0 | M38: =مورفولوژی!L31 -> 0 | N38: ='طبي انګلیسي'!L31 -> 0 | O38: ='عمومي ترمینالوژی'!L31 -> 0 | P38: =اسلامیات!L31 -> 0 | S38: 28
C39: =D39/12 -> 0 | D39: =SUM(E39:P39) -> 0 | E39: =PHC!L32 -> 0 | F39: =مایکروبیولوژی!L32 -> 0 | G39: ='متحرک پروتیز'!L32 -> 0 | H39: ='اناټومي فزیالوژی'!L32 -> 0 | I39: =پتالوژی!L32 -> 0 | J39: ='اختصاصي ترمینالوژی'!L32 -> 0 | K39: ='اختصاصي لابراتوار'!L32 -> 0 | L39: ='سامان پیژندنه'!L32 -> 0 | M39: =مورفولوژی!L32 -> 0 | N39: ='طبي انګلیسي'!L32 -> 0 | O39: ='عمومي ترمینالوژی'!L32 -> 0 | P39: =اسلامیات!L32 -> 0 | S39: 29
C40: =D40/12 -> 0 | D40: =SUM(E40:P40) -> 0 | E40: =PHC!L33 -> 0 | F40: =مایکروبیولوژی!L33 -> 0 | G40: ='متحرک پروتیز'!L33 -> 0 | H40: ='اناټومي فزیالوژی'!L33 -> 0 | I40: =پتالوژی!L33 -> 0 | J40: ='اختصاصي ترمینالوژی'!L33 -> 0 | K40: ='اختصاصي لابراتوار'!L33 -> 0 | L40: ='سامان پیژندنه'!L33 -> 0 | M40: =مورفولوژی!L33 -> 0 | N40: ='طبي انګلیسي'!L33 -> 0 | O40: ='عمومي ترمینالوژی'!L33 -> 0 | P40: =اسلامیات!L33 -> 0 | S40: 30
C41: =D41/12 -> 0 | D41: =SUM(E41:P41) -> 0 | E41: =PHC!L34 -> 0 | F41: =مایکروبیولوژی!L34 -> 0 | G41: ='متحرک پروتیز'!L34 -> 0 | H41: ='اناټومي فزیالوژی'!L34 -> 0 | I41: =پتالوژی!L34 -> 0 | J41: ='اختصاصي ترمینالوژی'!L34 -> 0 | K41: ='اختصاصي لابراتوار'!L34 -> 0 | L41: ='سامان پیژندنه'!L34 -> 0 | M41: =مورفولوژی!L34 -> 0 | N41: ='طبي انګلیسي'!L34 -> 0 | O41: ='عمومي ترمینالوژی'!L34 -> 0 | P41: =اسلامیات!L34 -> 0 | S41: 31
C42: =D42/12 -> 0 | D42: =SUM(E42:P42) -> 0 | E42: =PHC!L35 -> 0 | F42: =مایکروبیولوژی!L35 -> 0 | G42: ='متحرک پروتیز'!L35 -> 0 | H42: ='اناټومي فزیالوژی'!L35 -> 0 | I42: =پتالوژی!L35 -> 0 | J42: ='اختصاصي ترمینالوژی'!L35 -> 0 | K42: ='اختصاصي لابراتوار'!L35 -> 0 | L42: ='سامان پیژندنه'!L35 -> 0 | M42: =مورفولوژی!L35 -> 0 | N42: ='طبي انګلیسي'!L35 -> 0 | O42: ='عمومي ترمینالوژی'!L35 -> 0 | P42: =اسلامیات!L35 -> 0 | S42: 32
...
